<?xml version="1.0"?> 
<robot name="primeberry_one" xmlns:xacro="http://www.ros.org/wiki/xacro"> 

  <xacro:include filename="gazebo_control.xacro"/>
	
	<!-- World link -->  
  <link name="world">

  </link> 

	<!-- Chassis START-->  
	<joint name="base_joint" type="fixed">
        <origin xyz="1.5 1.0 0.0"/>
    <parent link="world"/> 
    <child link="chassis"/> 
  </joint> 

  <link name="chassis"> 
    <collision> 
      <!-- <origin xyz="0 0 0.3" rpy="0 0 0"/>  -->
      <geometry> 
            <box size="1 0.2 0.1"/> 
      </geometry> 
    </collision> 
    <visual> 
      <geometry> 
         <box size="1 0.2 0.1"/> 
      </geometry> 
      <material name="orange"/> 
    </visual> 
    <inertial> 
      <mass value="1"/> 
      <inertia ixx="0.4" ixy="0.1" ixz="0.1" iyy="0.4" iyz="0.1" izz="0.2"/> 
    </inertial> 
  </link>    

  <gazebo reference="chassis"> 
    <!--Stiffness -->  
    <kp>1000000.0</kp> 
    <!--Dampening-->  
    <kd>0.1</kd> 
    <dampingFactor>0</dampingFactor> 
    <material>Gazebo/White</material> 
    <selfCollide>true</selfCollide> 
    <turnGravityOff>false</turnGravityOff> 
    <mu1 value="0.1"/> 
    <mu2 value="0.1"/> 
    <fdir1 value="0 0 0"/> 
  </gazebo> 
	<!-- Chassis END --> 

  <!-- Right Wheel - Start --> 
	<link name="front_right_wheel"> 
		
		<collision> 
		  <origin xyz="0 0 0" rpy="0 1.5708 1.5708" />
		  <geometry> 
		   <cylinder length="0.05" radius="0.1"/> 
		  </geometry> 
		</collision> 

		<visual> 
		  <origin xyz="0 0 0" rpy="0 1.5708 1.5708" /> 
		  <geometry> 
			<cylinder length="0.05" radius="0.1"/> 
		  </geometry> 
		  <material name="black"/> 
		</visual> 		

		<inertial> 
		  <origin xyz="0 0 0" rpy="0 1.5708 1.5708" /> 
		  <mass value="0.2"/> 
		  <cylinder_inertia m="0.2" r="0.3" h="0.1"/> 
      <inertia ixx="0.4" ixy="0.1" ixz="0.1" iyy="0.4" iyz="0.1" izz="0.2"/> 
	  </inertial> 

	</link> 
  <gazebo reference="front_right_wheel"> 
    <mu1 value="2.0"/> 
    <mu2 value="2.0"/> 
    <kp  value="10000000.0" /> 
    <kd  value="1.0" /> 
    <fdir1 value="0 1 0"/> 
    <material>Gazebo/Blue</material> 
  </gazebo>

	<link name="front_right_wheel_assembly">
		<collision> 
		  <origin xyz="0 0 0" rpy="0 1.5708 1.5708" />
		  <geometry> 
		   <cylinder length="0.001" radius="0.04"/> 
		  </geometry> 
		</collision> 

		<visual> 
		  <origin xyz="0 0 0" rpy="0 1.5708 1.5708" /> 
		  <geometry> 
			<cylinder length="0.001" radius="0.04"/> 
		  </geometry> 
		  <material name="black"/> 
		</visual> 		

		<inertial> 
		  <origin xyz="0 0 0" rpy="0 1.5708 1.5708" /> 
		  <mass value="0.2"/> 
		  <cylinder_inertia m="0.2" r="0.3" h="0.1"/> 
      <inertia ixx="0.4" ixy="0.1" ixz="0.1" iyy="0.4" iyz="0.1" izz="0.2"/> 
	  </inertial>
	</link>  

  <gazebo reference="front_right_wheel_assembly"> 
    <mu1 value="2.0"/> 
    <mu2 value="2.0"/> 
    <kp  value="10000000.0" /> 
    <kd  value="1.0" /> 
    <fdir1 value="0 1 0"/> 
    <material>Gazebo/Black</material> 
  </gazebo>

  <joint name="front_right_wheel_hinge" type="revolute"> 
    <parent link="chassis"/> 
    <child link="front_right_wheel_assembly"/> 
    <origin xyz="0.4 0.1005 0.0" rpy="0 0 0" />  
    <axis xyz="0 0 1" rpy="0 0 0" /> 
    <limit effort="100" velocity="1" lower="-1" upper="1"/> 
    <dynamics damping="0.0" friction="0.0"/> 
  </joint> 

  <joint name="front_right_wheel_rotate" type="continuous"> 
    <parent link="front_right_wheel_assembly"/> 
    <child link="front_right_wheel"/> 
    <origin xyz="0.0 0.025 0.0" rpy="0 0 0" />  
    <axis xyz="0 1 0" rpy="0 0 0" /> 
    <limit effort="100" velocity="50"/> 
    <dynamics damping="0.0" friction="0.0"/> 
  </joint>


  <transmission name="trans_front_right_wheel_hing">
    <type>transmission_interface/SimpleTransmission</type>
    <joint name="front_right_wheel_hinge">
      <hardwareInterface>EffortJointInterface</hardwareInterface>
    </joint>
    <actuator name="motor1">
      <hardwareInterface>EffortJointInterface</hardwareInterface>
      <mechanicalReduction>1</mechanicalReduction>
    </actuator>
  </transmission>

  <transmission name="trans_front_right_wheel_rotate">
    <type>transmission_interface/SimpleTransmission</type>
    <joint name="front_right_wheel_rotate">
      <hardwareInterface>EffortJointInterface</hardwareInterface>
    </joint>
    <actuator name="motor_front_right_wheel_rotate">
      <hardwareInterface>EffortJointInterface</hardwareInterface>
      <mechanicalReduction>1</mechanicalReduction>
    </actuator>
  </transmission>

  <!-- Right Wheel - End -->  

  <!-- Left Wheel - Start  -->
	<link name="front_left_wheel"> 
		
		<collision> 
		  <origin xyz="0 0 0" rpy="0 1.5708 1.5708" />
		  <geometry> 
		   <cylinder length="0.05" radius="0.1"/> 
		  </geometry> 
		</collision> 

		<visual> 
		  <origin xyz="0 0 0" rpy="0 1.5708 1.5708" /> 
		  <geometry> 
			<cylinder length="0.05" radius="0.1"/> 
		  </geometry> 
		  <material name="black"/> 
		</visual> 		

		<inertial> 
		  <origin xyz="0 0 0" rpy="0 1.5708 1.5708" /> 
		  <mass value="0.2"/> 
		  <cylinder_inertia m="0.2" r="0.3" h="0.1"/> 
      <inertia ixx="0.4" ixy="0.1" ixz="0.1" iyy="0.4" iyz="0.1" izz="0.2"/> 
	  </inertial> 

	</link> 
  <gazebo reference="front_left_wheel"> 
    <mu1 value="2.0"/> 
    <mu2 value="2.0"/> 
    <kp  value="10000000.0" /> 
    <kd  value="1.0" /> 
    <fdir1 value="0 1 0"/> 
    <material>Gazebo/Black</material> 
  </gazebo>

	<link name="front_left_wheel_assembly">
		<collision> 
		  <origin xyz="0 0 0" rpy="0 1.5708 1.5708" />
		  <geometry> 
		   <cylinder length="0.001" radius="0.04"/> 
		  </geometry> 
		</collision> 

		<visual> 
		  <origin xyz="0 0 0" rpy="0 1.5708 1.5708" /> 
		  <geometry> 
			<cylinder length="0.001" radius="0.04"/> 
		  </geometry> 
		  <material name="black"/> 
		</visual> 		

		<inertial> 
		  <origin xyz="0 0 0" rpy="0 1.5708 1.5708" /> 
		  <mass value="0.2"/> 
		  <cylinder_inertia m="0.2" r="0.3" h="0.1"/> 
      <inertia ixx="0.4" ixy="0.1" ixz="0.1" iyy="0.4" iyz="0.1" izz="0.2"/> 
	  </inertial>
	</link>  

  <gazebo reference="front_left_wheel_assembly"> 
    <mu1 value="2.0"/> 
    <mu2 value="2.0"/> 
    <kp  value="10000000.0" /> 
    <kd  value="1.0" /> 
    <fdir1 value="0 1 0"/> 
    <material>Gazebo/Black</material> 
  </gazebo>

  <joint name="front_left_wheel_hinge" type="revolute"> 
    <parent link="chassis"/> 
    <child link="front_left_wheel_assembly"/> 
    <origin xyz="0.4 -0.1005 0.0" rpy="0 0 0" />  
    <axis xyz="0 0 1" rpy="0 0 0" /> 
    <limit effort="100" velocity="1" lower="-1" upper="1"/> 
    <dynamics damping="0.0" friction="0.0"/> 
  </joint> 

  <joint name="front_left_wheel_rotate" type="continuous"> 
    <parent link="front_left_wheel_assembly"/> 
    <child link="front_left_wheel"/> 
    <origin xyz="0.0 -0.025 0.0" rpy="0 0 0" />  
    <axis xyz="0 1 0" rpy="0 0 0" /> 
    <limit effort="0" velocity="0"/> 
    <dynamics damping="0.0" friction="0.0"/> 
  </joint>


  <transmission name="tran2">
    <type>transmission_interface/SimpleTransmission</type>
    <joint name="front_left_wheel_hinge">
      <hardwareInterface>EffortJointInterface</hardwareInterface>
    </joint>
    <actuator name="motor2">
      <hardwareInterface>EffortJointInterface</hardwareInterface>
      <mechanicalReduction>1</mechanicalReduction>
    </actuator>
  </transmission>

  <transmission name="trans_front_left_wheel_rotate">
    <type>transmission_interface/SimpleTransmission</type>
    <joint name="front_left_wheel_rotate">
      <hardwareInterface>EffortJointInterface</hardwareInterface>
    </joint>
    <actuator name="motor_front_left_wheel_rotate">
      <hardwareInterface>EffortJointInterface</hardwareInterface>
      <mechanicalReduction>1</mechanicalReduction>
    </actuator>
  </transmission>

  <!-- Left Wheel - End -->

  <!-- Right Rear Wheel Start -->
	<link name="right_wheel_rear"> 
		
		<collision> 
		  <origin xyz="0 0 0" rpy="0 1.5708 1.5708" />
		  <geometry> 
		   <cylinder length="0.05" radius="0.1"/> 
		  </geometry> 
		</collision> 

		<visual> 
		  <origin xyz="0 0 0" rpy="0 1.5708 1.5708" /> 
		  <geometry> 
			<cylinder length="0.05" radius="0.1"/> 
		  </geometry> 
		  <material name="black"/> 
		</visual> 		

		<inertial> 
		  <origin xyz="0 0 0" rpy="0 1.5708 1.5708" /> 
		  <mass value="0.2"/> 
		  <cylinder_inertia m="0.2" r="0.3" h="0.1"/> 
      <inertia ixx="0.4" ixy="0.1" ixz="0.1" iyy="0.4" iyz="0.1" izz="0.2"/> 
	  </inertial> 

	</link>

  <joint name="right_wheel_rear_rotate" type="continuous"> 
    <parent link="chassis"/> 
    <child link="right_wheel_rear"/> 
    <origin xyz="-0.4 0.125 0.0" rpy="0 0 0" />  
    <axis xyz="0 1 0" rpy="0 0 0" /> 
    <limit effort="0" velocity="0"/> 
    <dynamics damping="0.0" friction="0.0"/> 
  </joint>

  <gazebo reference="right_wheel_rear"> 
    <mu1 value="2.0"/> 
    <mu2 value="2.0"/> 
    <kp  value="10000000.0" /> 
    <kd  value="1.0" /> 
    <fdir1 value="0 1 0"/> 
    <material>Gazebo/Black</material> 
  </gazebo>

  <!-- Right Rear Wheel End -->

    <!-- Right Rear Wheel Start -->
	<link name="left_wheel_rear"> 
		
		<collision> 
		  <origin xyz="0 0 0" rpy="0 1.5708 1.5708" />
		  <geometry> 
		   <cylinder length="0.05" radius="0.1"/> 
		  </geometry> 
		</collision> 

		<visual> 
		  <origin xyz="0 0 0" rpy="0 1.5708 1.5708" /> 
		  <geometry> 
			<cylinder length="0.05" radius="0.1"/> 
		  </geometry> 
		  <material name="black"/> 
		</visual> 		

		<inertial> 
		  <origin xyz="0 0 0" rpy="0 1.5708 1.5708" /> 
		  <mass value="0.2"/> 
		  <cylinder_inertia m="0.2" r="0.3" h="0.1"/> 
      <inertia ixx="0.4" ixy="0.1" ixz="0.1" iyy="0.4" iyz="0.1" izz="0.2"/> 
	  </inertial> 

	</link>

  <joint name="left_wheel_rear_rotate" type="continuous"> 
    <parent link="chassis"/> 
    <child link="left_wheel_rear"/> 
    <origin xyz="-0.4 -0.125 0.0" rpy="0 0 0" />  
    <axis xyz="0 1 0" rpy="0 0 0" /> 
    <limit effort="0" velocity="0"/> 
    <dynamics damping="0.0" friction="0.0"/> 
  </joint>

  <gazebo reference="left_wheel_rear"> 
    <mu1 value="2.0"/> 
    <mu2 value="2.0"/> 
    <kp  value="10000000.0" /> 
    <kd  value="1.0" /> 
    <fdir1 value="0 1 0"/> 
    <material>Gazebo/Blue</material> 
  </gazebo>

  <!-- Left Rear Wheel End -->


</robot> 